Workbook

Sheet Lotes
A1: Código do Produto | B1: Descrição | C1: LOTE | D1: VALIDADE
A2: 107033200 | B2: AGUA PERF PATCHOULI 200ML | C2: D1943 | D2: 04/28
A3: 106012250 | B3: AGUA PERF SPLASH LOTUS PATBO 250ML | C3: H2178 | D3: 08/28
A4: 106071250 | B4: AGUA PERF SPLASH SUMMER PATBO 250ML | C4: K2363 | D4: 11/28
A5: 106028250 | B5: AGUA PERF SPLASH VANILLA PATBO 250ML | C5: J2283 | D5: 10/28
A6: 106384200 | B6: AGUA PERFUMADA ALECRIM MEDITERANEO ARABESC - 200ML | C6: 3227 | D6: 02/28
A7: 106084001 | B7: AGUA PERFUMADA ALECRIM MEDITERRANEO ARABESC - 1L | C7: K2372 | D7: 11/28
A8: 106084500 | B8: AGUA PERFUMADA ALECRIM MEDITERRANEO ARABESC - 500ML | C8: K2359 | D8: 12/28
A9: 107011500 | B9: AGUA PERFUMADA CITRUS VERBENA ARABESC - 500ML | C9: A2415 | D9: 01/29
A10: 107009500 | B10: AGUA PERFUMADA FIGO AMBARADO ARABESC - 500ML | C10: LEN101.0003 | D10: 01/29
A11: 107079500 | B11: AGUA PERFUMADA FLOR DE LARANJEIRA ELEMENTOS - 500ML | C11: 32470 | D11: 02/29
A12: 107001600 | B12: AGUA PERFUMADA FOUNTAIN CLASSIC - 500ML | C12: A2421 | D12: 01/29
... A64: 105068130 | B64: DIFUSOR DE PERFUME HAPPY PLACE SMILEY - 130ML | C64: 1728 | D64: 03/26
A65: 105003201 | B65: DIFUSOR DE PERFUME INTO THE NIGHT CLASSIC - 250ML | C65: L2412 | D65: 12/28 | F65: OK
A66: 105003001 | B66: DIFUSOR DE PERFUME INTO THE NIGHT DECOR - 220ML | C66: LEN1.0019 | D66: 12/27
A67: 10657220 | B67: DIFUSOR DE PERFUME INTO THE NIGHT URBAN - 230ML | C67: - | D67: -
A68: 105012250 | B68: DIFUSOR DE PERFUME LAVANDA ABSOLUTA ARABESC - 200ML | C68: LEN174.0005 | D68: 12/28
A69: 105017200 | B69: DIFUSOR DE PERFUME LEGNO DI MALTA ELEMENTOS - 200ML | C69: C1912 | D69: 03/28
A70: 105039130 | B70: DIFUSOR DE PERFUME LIMONCELLO LENVIE & BACIO DI LATTE - 130ML | C70: J2306 | D70: 10/28
A71: 105040200 | B71: DIFUSOR DE PERFUME LOTUS GARDEN LENVIE-PATBO - 200ML | C71: LEN79.0010 | D71: 02/29
A72: 105002201 | B72: DIFUSOR DE PERFUME LUMIERE CLASSIC - 250ML | C72: J2249 | D72: 10/28
A73: 105013250 | B73: DIFUSOR DE PERFUME MAGNOLIA PACIFICA ARABESC - 200ML | C73: LEN5.0023 | D73: 11/28
A74: 105013001 | B74: DIFUSOR DE PERFUME MAGNOLIA PACIFICA DECOR - 220ML | C74: LEN32.0027 | D74: 02/28
A75: 10659220 | B75: DIFUSOR DE PERFUME MAGNOLIA PACIFICA URBAN - 230ML | C75: - | D75: -
A76: 105027250 | B76: DIFUSOR DE PERFUME MAMY CARNEIRINHO - 250ML | C76: K2340 | D76: 11/28
A77: 105074200 | B77: DIFUSOR DE PERFUME MANDARINA CEYLON - 200ML | C77: B2468 | D77: 02/29
... A127: 104012230 | B127: HOME SPRAY LAVANDA ABSOLUTA ARABESC - 200ML | C127: 273 | D127: 11/28
A128: 104012231 | B128: HOME SPRAY LAVANDA ABSOLUTA ARABESC - 200ML
A129: 104017200 | B129: HOME SPRAY LEGNO DI MALTA - 200ML | C129: J2294 | D129: 10/28
A130: 104017201 | B130: HOME SPRAY LEGNO DI MALTA - 200ML | C130: J2294 | D130: 10/28
A131: 104002100 | B131: HOME SPRAY LUMIERE CLASSIC - 100ML | C131: B1875 | D131: 02/28
A132: 104013100 | B132: HOME SPRAY MAGNOLIA PACIFICA ARABESC - 100ML | C132: 251 | D132: 11/28
A133: 104013999 | B133: HOME SPRAY MAGNOLIA PACIFICA ARABESC - 1L | C133: HLMP25071 | D133: 07/27
A134: 104013230 | B134: HOME SPRAY MAGNOLIA PACIFICA ARABESC - 200ML | C134: 250 | D134: 11/28
A135: 104013200 | B135: HOME SPRAY MAGNOLIA PACIFICA ARABESC - 200ML
A136: 104027250 | B136: HOME SPRAY MAMY CARNEIRINHO - 250ML | C136: J2267 | D136: 10/28
A137: 104015999 | B137: HOME SPRAY MANDARINA CEYLON ARABESC - 1L | C137: LHLMA26011 | D137: 01/28
A138: 104074200 | B138: HOME SPRAY MANDARINA CEYLON ARABESC - 200ML | C138: 186 | D138: 10/28
A139: 104188200 | B139: HOME SPRAY MUSGO DE CARVALHO ELEMENTOS - 200ML | C139: 336 | D139: 12/28
A140: 104033100 | B140: HOME SPRAY PATCHOULI VANILLA ARABESC - 100ML | C140: 388 | D140: 01/29
...

Sheet Kits
A1: Código item | C1: Código do Produto | D1: Descrição | E1: LOTE | F1: VALIDADE
A2: 107027500 | B2: 105027250 | C2: 10705027 | D2: KIT MAMY AGUA 500ML E DIF 250ML | E2: {=CONCATENATE(XLOOKUP($A2,Lotes!$A:$A,Lotes!$C:$C),"/",XLOOKUP($B2,Lotes!$A:$A,Lotes!$C:$C))} -> A2416/K2340 | F2: {=XLOOKUP($A2,Lotes!$A:$A,Lotes!$D:$D)} -> 01/29
A3: 107027500 | B3: 104027250 | C3: 10704027 | D3: KIT MAMY AGUA 500ML E HOME SPRAY 250ML | E3: {=CONCATENATE(XLOOKUP($A3,Lotes!$A:$A,Lotes!$C:$C),"/",XLOOKUP($B3,Lotes!$A:$A,Lotes!$C:$C))} -> A2416/J2267 | F3: {=XLOOKUP($A3,Lotes!$A:$A,Lotes!$D:$D)} -> 01/29
C4: 11802150 | E4: {=CONCATENATE(XLOOKUP($A4,Lotes!$A:$A,Lotes!$C:$C),"/",XLOOKUP($B4,Lotes!$A:$A,Lotes!$C:$C))} -> #N/A | F4: {=XLOOKUP($A4,Lotes!$A:$A,Lotes!$D:$D)} -> #N/A
A5: 10139260 | C5: 10139274 | D5: KIT AROMATIZADOR ELETRICO + BARRA DE CERA PERFUMADA FIGO AMBARADO 40G | E5: {=XLOOKUP($A5,Lotes!$A:$A,Lotes!$C:$C)} -> 2025210BLEFA | F5: {=XLOOKUP($A5,Lotes!$A:$A,Lotes!$D:$D)} -> 02/27
A6: 10134060 | C6: 10134074 | D6: KIT AROMATIZADOR ELETRICO + BARRA DE CERA PERFUMADA FLOR DE LARANJEIRA 40G | E6: {=XLOOKUP($A6,Lotes!$A:$A,Lotes!$C:$C)} -> 20252207BLEFL | F6: {=XLOOKUP($A6,Lotes!$A:$A,Lotes!$D:$D)} -> 07/27
A7: 1013747460 | C7: 10137474 | D7: KIT AROMATIZADOR ELETRICO + BARRA DE CERA PERFUMADA MAGNOLIA PACIFICA 40G | E7: {=XLOOKUP($A7,Lotes!$A:$A,Lotes!$C:$C)} -> 20252207BLEMA | F7: {=XLOOKUP($A7,Lotes!$A:$A,Lotes!$D:$D)} -> 07/27
A8: 10131860 | C8: 10131874 | D8: KIT AROMATIZADOR ELETRICO + BARRA DE CERA PERFUMADA SUNSET ROSE 40G | E8: {=XLOOKUP($A8,Lotes!$A:$A,Lotes!$C:$C)} -> 20252602BLESR | F8: {=XLOOKUP($A8,Lotes!$A:$A,Lotes!$D:$D)} -> 02/27
A9: 114063020 | C9: 14099020 | D9: KIT AROMATIZADOR ELETRICO + OLEO CONCENTRADO FIGO AMBARADO - 20ML | E9: {=XLOOKUP($A9,Lotes!$A:$A,Lotes!$C:$C)} -> OLFA2506 | F9: {=XLOOKUP($A9,Lotes!$A:$A,Lotes!$D:$D)} -> 06/27
A10: 114067020 | C10: 14097920 | D10: KIT AROMATIZADOR ELETRICO + OLEO CONCENTRADO FLOR DE LANJEIRA - 20ML | E10: {=XLOOKUP($A10,Lotes!$A:$A,Lotes!$C:$C)} -> OLFL2510 | F10: {=XLOOKUP($A10,Lotes!$A:$A,Lotes!$D:$D)} -> 10/27
A11: 114049020 | C11: 14090020 | D11: KIT AROMATIZADOR ELETRICO + OLEO CONCENTRADO INTO THE NIGHT - 20ML | E11: {=XLOOKUP($A11,Lotes!$A:$A,Lotes!$C:$C)} -> OLIN2508 | F11: {=XLOOKUP($A11,Lotes!$A:$A,Lotes!$D:$D)} -> 08/27
A12: 114020020 | C12: 14012020 | D12: KIT AROMATIZADOR ELETRICO + OLEO CONCENTRADO LAVANDA ABSOLUTA - 20ML | E12: {=XLOOKUP($A12,Lotes!$A:$A,Lotes!$C:$C)} -> OLLA2511 | F12: {=XLOOKUP($A12,Lotes!$A:$A,Lotes!$D:$D)} -> 11/27
A13: 114022020 | C13: 14093020 | D13: KIT AROMATIZADOR ELETRICO + OLEO CONCENTRADO MAGNOLIA PACIFICA - 20ML | E13: {=XLOOKUP($A13,Lotes!$A:$A,Lotes!$C:$C)} -> OLMP2512 | F13: {=XLOOKUP($A13,Lotes!$A:$A,Lotes!$D:$D)} -> 12/27
A14: 114074020 | C14: 14090220 | D14: KIT AROMATIZADOR ELETRICO + OLEO CONCENTRADO MANDARINA CEYLON - 20ML | E14: {=XLOOKUP($A14,Lotes!$A:$A,Lotes!$C:$C)} -> OLMC | F14: {=XLOOKUP($A14,Lotes!$A:$A,Lotes!$D:$D)} -> 12/27
A15: 114032020 | C15: 14093320 | D15: KIT AROMATIZADOR ELETRICO + OLEO CONCENTRADO PATCHOULI VANILLA - 20ML | E15: {=XLOOKUP($A15,Lotes!$A:$A,Lotes!$C:$C)} -> OLPV2510 | F15: {=XLOOKUP($A15,Lotes!$A:$A,Lotes!$D:$D)} -> 10/27
A16: 114061020 | C16: 14098020 | D16: KIT AROMATIZADOR ELETRICO + OLEO CONCENTRADO SUNSET ROSE - 20ML | E16: {=XLOOKUP($A16,Lotes!$A:$A,Lotes!$C:$C)} -> OLSR2510 | F16: {=XLOOKUP($A16,Lotes!$A:$A,Lotes!$D:$D)} -> 10/27
... A30: 1013747460 | C30: 14109640 | D30: KIT MAGNOLIA BARRA DE CERA 40G 10 UN | E30: {=XLOOKUP($A30,Lotes!$A:$A,Lotes!$C:$C)} -> 20252207BLEMA | F30: {=XLOOKUP($A30,Lotes!$A:$A,Lotes!$D:$D)} -> 07/27
